Workbook

Sheet Cars_dataset_sheet1
A1: Ad ID | B1: Car_Name | C1: Make | D1: Make Model | E1: Year | F1: KM_driven | G1: Price
A2: 1019823763 | B2: Toyota Corolla Altis 1.6 cc | C2: Toyota | D2: Toyota Corrolla Altis | E2: 2015 | F2: 130000 | G2: 4000000
A3: 1032353392 | B3: Mitsubishi mini cab urgent sale | C3: Mitsubishi | D3: Mitsubishi Minica | E3: 2012 | F3: 115000 | G3: 1150000
A4: 1035626806 | B4: Suzuki Every 2013 Model 2019 Registered Jet Black Single hand Use A+ C | C4: Suzuki | D4: Suzuki Every | E4: 2013 | F4: 120000 | G4: 1900000
A5: 1036683049 | B5: Mehran 2016 VXR original condition | C5: Suzuki | D5: Suzuki Mehran VXR | E5: 2016 | F5: 38500 | G5: 1180000
A6: 1036970933 | B6: Daihatsu Cuore 2004 | C6: Daihatsu | D6: Daihatsu Cuore | E6: 2004 | F6: 100000 | G6: 700000
A7: 1038612589 | B7: Mitsubishi Minica 2 door Japanese Car for sale | C7: Mitsubishi | D7: Mitsubishi Minica | E7: 2007 | F7: 133500 | G7: 1300000
A8: 1043285959 | B8: toyota corolla 2005 | C8: Toyota | D8: Toyota Corolla XLI | E8: 2005 | F8: 195000 | G8: 1750000
A9: 1043893641 | B9: chska party call na kra | C9: KIA | D9: KIA Classic | E9: 2005 | F9: 129049 | G9: 550000
A10: 1045295959 | B10: Suzuki Wagon R FA Package 2019 Model 2022 Fresh Import 17360 Km driven | C10: Suzuki | D10: Suzuki Wagon R | E10: 2019 | F10: 18360 | G10: 3500000
A11: 1045445134 | B11: Carry Daaba Minicap Mitsubishi | C11: Mitsubishi | D11: Mitsubishi Minica | E11: 2017 | F11: 170000 | G11: 1500000
A12: 1046475308 | B12: Kia Spectra 2001 1.5 Automatic. Customised price negotiable hai jaldi | C12: KIA | D12: KIA Spectra | E12: 2001 | F12: 50000 | G12: 1200000
A13: 1046608801 | B13: suzuki every turbo 5gair Exchange posibl with Honda&corola 03195517118 | C13: Suzuki | D13: Suzuki Every | E13: 2016 | F13: 123456 | G13: 1750000
... A498: 1076289664 | B498: Carry Bolin | C498: Suzuki | D498: Suzuki Bolan | E498: 2019 | F498: 12345 | G498: 1350000
A499: 1076304786 | B499: 3119111071 | C499: Suzuki | D499: Suzuki Bolan | E499: 2010 | F499: 70000 | G499: 850000
A500: 1076307705 | B500: Dihatshu Mira 2012/15 New Condition Exchange with Alto Vxr | C500: Daihatsu | D500: Daihatsu Mira | E500: 2015 | F500: 99000 | G500: 2300000
A501: 1076311882 | B501: Mehran VXR 2008 | C501: Suzuki | D501: Suzuki Mehran VXR | E501: 2008 | F501: 50000 | G501: 750000
A502: 1076312655 | B502: KIA PICANTO 1.0 AT | C502: KIA | D502: KIA Picanto | E502: 2021 | F502: 18500 | G502: 3150000
A503: 1076320957 | B503: City 2009 -Prosmatic | C503: Honda | D503: Honda City IVTEC | E503: 2009 | F503: 146000 | G503: 2200000
A504: 1076322359 | B504: Santro Club 2004 Urgent Sale | C504: Hyundai | D504: Hyundai Santro | E504: 2004 | F504: 99000 | G504: 650000
A505: 1076323992 | B505: Mira Package XSA3 Like a Brand New Car | C505: Daihatsu | D505: Daihatsu Mira | E505: 2019 | F505: 115000 | G505: 3550000
A506: 1076340262 | B506: Carolla Altis 1.6 | C506: Toyota | D506: Toyota Corrolla Altis | E506: 2017 | F506: 90000 | G506: 3900000
A507: 1076347671 | B507: KIA SPECTRA IN V GOOD CONDITION. (O3OO55O6699) | C507: KIA | D507: KIA Spectra | E507: 2002 | F507: 1234 | G507: 520000
A508: 1076356020 | B508: every 07/12 for sale or Xchang Toyota car | C508: Suzuki | D508: Suzuki Every | E508: 2012 | F508: 200000 | G508: 1260000
A509: 1076380433 | B509: suzuki Alto vxr | C509: Suzuki | D509: Suzuki Alto | E509: 2012 | F509: 143000 | G509: 1020000
A510: 1076380992 | B510: Altis 1.6 automatic 2020/2021 for sale | C510: Toyota | D510: Toyota Corrolla Altis | E510: 2020 | F510: 58000 | G510: 4400000
A511: 1076385717 | B511: Hyndai santro club 2003 | C511: Hyundai | D511: Hyundai Santro | E511: 2003 | F511: 5555 | G511: 780000
... A730: 1077566598 | B730: 1.5 Honda City Aspire in Brand New Condition | C730: Honda | D730: Honda City Aspire | E730: 2017 | F730: 51000 | G730: 3250000
A731: 1077567793 | B731: 3002195137 | C731: Suzuki | D731: Suzuki Bolan | E731: 2017 | F731: 62000 | G731: 1150000
A732: 1077572197 | B732: Mitsubishi Lancer 2005 model in good condition | C732: Mitsubishi | D732: Mitsubishi Lancer | E732: 2005 | F732: 70000 | G732: 1370000
A733: 1077576628 | B733: dihatsu move urgent sale | C733: Daihatsu | D733: Daihatsu Move | E733: 2021 | F733: 100000 | G733: 2900000
A734: 1077577910 | B734: honda city 2010 | C734: Honda | D734: Honda City IVTEC | E734: 2010 | F734: 145000 | G734: 2500000
A735: 1077578497 | B735: Honda civic reborn | C735: Honda | D735: Honda Civic Prosmetic | E735: 2009 | F735: 97000 | G735: 1800000
A736: 1077580298 | B736: Cuore 2012 | C736: Daihatsu | D736: Daihatsu Cuore | E736: 2012 | F736: 120000 | G736: 865000
A737: 1077583006 | B737: honda city 1.3 Mt | C737: Honda | D737: Honda City IVTEC | E737: 2019 | F737: 58000 | G737: 3500000
A738: 1077583460 | B738: Ek Wagon 2008/2013 [660cc] | C738: Mitsubishi | D738: Mitsubishi Ek Wagon | E738: 2008 | F738: 140000 | G738: 1700000
A739: 1077592008 | B739: Mercedes C 200 Kompressor | C739: Mercedes | D739: Mercedes C Class | E739: 2003 | F739: 200000 | G739: 2300000
A740: 1077609801 | B740: i am selling my lancer glx 1.5 automatic | C740: Mitsubishi | D740: Mitsubishi Lancer | E740: 2006 | F740: 65000 | G740: 1550000
A741: 1077612923 | B741: Mira model 2014 registration 2017 | C741: Daihatsu | D741: Daihatsu Mira | E741: 2014 | F741: 119000 | G741: 2460000
A742: 1077614644 | B742: Honda City IDSI Vario | C742: Honda | D742: Honda City Vario | E742: 2007 | F742: 79000 | G742: 1680000
...

Sheet Cars_dataset_sheet2
A1: Ad ID | B1: Fuel | C1: Registration_city | D1: Car_documents | E1: Seller_Location | F1: Description | G1: Assembly | H1: Transmission | I1: Condition
A2: 1080762189 | B2: Petrol | C2: Karachi | D2: Original | E2: Awan Town, Lahore | F2: I m selling my swift car, very good condition total janiun. Like New car. First hand used only driven 65000 I m second owner. Price almost final but slightly negushiat. Home used car. Just buy and drive. Serious buyer just text. No call | G2: Local | H2: Manual | I2: Used
A3: 1080784426 | B3: Petrol | C3: Lahore | D3: Original | E3: DHA Defence, Karachi | F3: Suzuki Swift 1.3 DLX 2014 Model. 2nd Owner. 40000kms Driven. Sparingly Used. Entirely Genuine and Scratch Less. . Throughout Petrol Driven. Expensive Rims and new Tires installed recently. Leather Seats. New Battery. Absolutely no work required. Buy and Drive. All Documents Complete. Taxes upto Date. Calls only | G3: Local | H3: Manual | I3: Used
A4: 1060740152 | B4: Petrol | C4: Lahore | D4: Original | E4: Bahria Town Phase 8, Rawalpindi | F4: Suzuki marhan 2017 model | G4: Local | H4: Manual | I4: Used
A5: 1063029544 | B5: Petrol | C5: Karachi | D5: Original | E5: Royal 8 Icon, Karachi | F5: URGENT CASH NEEDED. AUTO coverted installed with 1500cc EFI japanese engine,( Not updated on book). Car is in excellent working condition new suspension and steering system installed for good maneuvering and smooth drive, installed with working AC, power windows and power steering, android system and speakers also installed. all oils changed. soundless and water dropping engine. only tikli is missing. showered from outside. undercoat is done with european standard paint. no rust on the body. tax is around 27,000 and will be paid by the buyer on finalization of deal. documents are complete only the first 2 books are missing but current book is available. contact on whatsapp if number not being received please. Reason for selling is it is in excess at home | G5: Local | H5: Automatic | I5: Used
A6: 1068252730 | B6: Petrol | C6: Lahore | D6: Original | E6: Aziz Bhatti Shaheed Road, Sialkot | F6: honda city total orgnall family use urgent sale and exchange auto car | G6: Local | H6: Manual | I6: Used
A7: 1068494302 | B7: Petrol | C7: Lahore | D7: Original | E7: Aziz Bhatti Shaheed Road, Sialkot | F7: honda city somth new condition family use orgnall urgent sale and exchange auto | G7: Local | H7: Manual | I7: Used
A8: 1068567690 | B8: Petrol | C8: Karachi | D8: Original | E8: Gulshan-e-Iqbal, Karachi | F8: 1st owner fully maintained smells like new full original water dropping engine | G8: Local | H8: Automatic | I8: Used
A9: 1070497471 | B9: Petrol | C9: Karachi | D9: Original | E9: DHA Defence, Karachi | F9: Honda City prosmatic 1.3 low mileage original bumper to Bumper just like new. model 2018 November 2nd owner in my name. New Yokohama blue earth tyres | G9: Local | H9: Automatic | I9: Used
A10: 1072822149 | B10: Petrol | C10: Karachi | D10: Original | E10: Allahwala Town, Karachi | F10: Yaris 2023 Gli Manual 1.3 silver Colour price full and final hayn | G10: Local | H10: Manual | I10: Used
A11: 1073368879 | B11: Petrol | C11: Faisalabad | D11: Original | E11: Faisalabad, Punjab | F11: Baher say Sara paint hai or documents original hai. | G11: Local | H11: Manual | I11: Used
A12: 1074728073 | B12: Petrol | C12: Karachi | D12: Original | E12: Nazimabad 1, Karachi | F12: my car is sale good condition LCD back camera power starting power window all documents clear original CPLC killer only home use car all system working Koi Kam Nahin hai bus lo chalao new tyre only call no message barai meherbani only call | G12: Local | H12: Manual | I12: Used
A13: 1075945797 | B13: Petrol | C13: Lahore | D13: Original | E13: Depalpur Road, Okara | F13: bolan cary daba purches date 2019 model | G13: Imported | H13: Manual | I13: Used
... A406: 1072408950 | B406: Petrol | C406: Faisalabad | D406: Original | E406: Faisalabad, Punjab | F406: Minor tuchup room total janwan fresh look dacoments clear bayometrc on spot | G406: Local | H406: Manual | I406: Used
A407: 1072411638 | B407: Petrol | C407: Sindh | D407: Original | E407: Airport Enclave, Islamabad | F407: 3345154198 | G407: Imported | H407: Manual | I407: Used
A408: 1072423579 | B408: Petrol | C408: Islamabad | D408: Original | E408: Palm City, Rawalpindi | F408: Selling Toyota Passo 2007 Model 2012 Import Engine Capicity at 70-75%. All in Original Color. Only Bumpers are painted. REST OF THE BODY IS IN ORIGINAL CONDITION. | G408: Imported | H408: Automatic | I408: Used
A409: 1072423748 | B409: Petrol | C409: Punjab | D409: Original | E409: Canal View, Lahore | F409: AoA. i want to sell my total genuine, scratchless, neat and clean car. Car in in my own name. Its drive is just like new car. Price is almost final, Only serious buyers may contact. Leather poshish and LCD installed. | G409: Local | H409: Manual | I409: Used
A410: 1072502304 | B410: Petrol | C410: Lahore | D410: Original | E410: Mushtaq Colony, Lahore | F410: I am a selling a 2 door Mitsubishi Manica car. 16-18KM/L. Ac is perfect ok , suspension perfect smart card and original documents are available. if you want to buy just text me. or call me on | G410: Imported | H410: Automatic | I410: Used
A411: 1072606415 | B411: Petrol | C411: Gujranwala | D411: Original | E411: Safdar Abad, SheikhÃ¼pura | F411: Alloy Rim good condition back cemra LCD mp3 player instaled just buy and drive no work required all original documents available | G411: Local | H411: Manual | I411: Used
A412: 1072657831 | B412: Petrol | C412: Karachi | D412: Original | E412: Soan Garden, Islamabad | F412: Toyota Altis 2016 Very good condition. No work is required at all. Almost 89000 km driven with good care like a girlfriend only One piece touch-up. Come with your mechanic and Denter. Recently done routine check-ups with Toyota Creek, bills are available for your satisfaction. Transmission Oil and engine oil were changed at 89000 KM through the Toyota Creek bills are also available for your satisfaction. The price of the car is final and there will be no change so please call if you agree with this amount otherwise don't call | G412: Local | H412: Automatic | I412: Used
A413: 1072671849 | B413: Petrol | C413: Lahore | D413: Original | E413: Madina Town, Faisalabad | F413: Daihatsu mira es All documents available biometric available Brighstone new tires with spare tire Light weight alloy rims installed Family used car LCD panel installed 4.5 grade car from Japan non accident car WhatsApp number= | G413: Imported | H413: Automatic | I413: Used
A414: 1072673258 | B414: Petrol | C414: Multan | D414: Original | E414: Others, Arifwala | F414: Suzuki Cultus VXR 2006 no work required smooth drive bio availiable 2nd onwer body 90% ok inter geniune price already negotiate serious buyer contact me no foolish offer only call | G414: Imported | H414: Manual | I414: Used
A415: 1072797519 | B415: Petrol | C415: Karachi | D415: Original | E415: Kohsar, Hyderabad | F415: engine 10/10 tyre 10/10 original bumper to bumper genuine family used car tax upto date Ac chilled sound system ju lega woh transfer krwaye ga apny nam pe | G415: Imported | H415: Manual | I415: Used
A416: 1072845373 | B416: Petrol | C416: Lahore | D416: Original | E416: Yaqoob Abad, Burewala | F416: I am sale car Suzuki Khyber engine modified mira daihtsu 660 cc good petrol average chil Ac original phle car chq kry phir rate ki bat kry | G416: Imported | H416: Automatic | I416: Used
A417: 1072911802 | B417: Petrol | C417: Islamabad | D417: Original | E417: I-8 Markaz, Islamabad | F417: Suzuki Mehran 2015 VXR mechanically perfect new tyres complete documents lifetime tokens paid Price slightly negotiable | G417: Local | H417: Manual | I417: Used
A418: 1072936521 | B418: Petrol | C418: Lahore | D418: Original | E418: Jhang City, Jhang | F418: Car is total genuine condition . One hand Home Used Family car . no denting no painting. Biomatric also available . No work required just buy and drive . Gift for toyota lover . 68000 milage only. Fresh car . 13+ average Alhamdulillah. | G418: Local | H418: Automatic | I418: Used
A419: 1072976575 | B419: Petrol | C419: Lahore | D419: Original | E419: Mehrpura Sharqi, Attock | F419: Suzuki mehran all ok carry daba Kay Sath matcha ho saka hai up model ho | G419: Local | H419: Manual | I419: Used
... A2002: 1079544325 | B2002: Petrol | C2002: Karachi | D2002: Original | E2002: Gulistan-e-Jauhar, Karachi | F2002: 1st owner no touchups no shower full genuine paint spare key unused all user manual available one hand driven only serious buyers can call | G2002: Local | H2002: Automatic | I2002: Used
A2003: 1079544851 | B2003: Petrol | C2003: Karachi | D2003: Original | E2003: Allama Iqbal Town, Lahore | F2003: #NAME? | G2003: Local | H2003: Manual | I2003: Used
A2004: 1079544992 | B2004: Petrol | C2004: Lahore | D2004: Original | E2004: GT Road, Muridike | F2004: honda city 2010 1.3 manual mint condition engine 10/10 Non accident body condition 9/10 total genuine except diggii alloy rims interior used 9.5/10 Mostly used in home suspension 9/10 WhatsApp for visiting! thanks in advance. | G2004: Local | H2004: Manual | I2004: Used
A2005: 1079545075 | B2005: Petrol | C2005: Karachi | D2005: Original | E2005: DHA Phase 2 Extension, Karachi | F2005: MAKE TOYOTA COROLLA VARIENT ALTIS 1.6 MODEL 2015 REG 2015 COLOUR SUPER WHITE BODY TOTAL ORIGINAL MILEAGE 73000km (NOTE) :- Toyota Corolla Altis 1.6 IMMACULATE CONDITION, TOTAL ORIGINAL NEW TYRES,Everything 100% | G2005: Local | H2005: Automatic | I2005: Used
A2006: 1079547680 | B2006: Petrol | C2006: Lahore | D2006: Original | E2006: Others, Khanewal | F2006: City b2b genuine 1.3 manual. b2b means b2b. white colour price is slightly negotiable. Only serious person should contact. Car is in kabirwala | G2006: Local | H2006: Manual | I2006: Used
A2007: 1079550264 | B2007: Petrol | C2007: Islamabad | D2007: Original | E2007: B-17, Islamabad | F2007: Toyota passo Hana plus Limited edition Top variant. Full options Sofa seat . Climate control AC Model 2012 Islamabad number Full genuine. No touching. No paint. No spray. Seal by seal. Projected light Original smart card on my own name. Fresh biometric available. Red wine colour Keyless entry. New tyre. Engine water throwing. Fuel average On long 18 On local 16 average. Army Officer used car proof available Car can be seen at sector B-17 Multigarden Islamabad anytime. | G2007: Imported | H2007: Automatic | I2007: Used
A2008: 1079550726 | B2008: Petrol | C2008: Karachi | D2008: Original | E2008: Nazimabad, Karachi | F2008: Selling my Honda city aspire manual transmission side tochups some due to scratch inner genuine neat and clean car first owner Android installed new battery new tyres installed recently each and every thing clear can I kept with care as seen in pics interested just call here | G2008: Local | H2008: Manual | I2008: Used
A2009: 1079552812 | B2009: Petrol | C2009: Karachi | D2009: Original | E2009: PECHS, Karachi | F2009: cultus 2014 registerd 2015 family used car jus buy and drive pechs block 6 0346/233/5231 timing 9 to 6 | G2009: Local | H2009: Manual | I2009: Used
A2010: 1079560221 | B2010: Petrol | C2010: Rawalpindi | D2010: Original | E2010: Mian Khel Bazar, Kohat | F2010: Ø§Ú†Ú¾ÛŒ Ú©Ù†ÚˆÛŒØ´Ù† Û”ØµØ§Ù Ø³ØªÚ¾Ø±ÛŒ Ú¯Ø§Ú‘ÛŒ Û”Ú¯Ú¾Ø± Ú©Û’ Ø§Ø³ØªØ¹Ù…Ø§Ù„ Ú©ÛŒ Û”Ú©ÙˆØ¦ÛŒ Ú©Ø§Ù… Ù†ÛÛŒÚº Û”Ø®Ø±ÛŒØ¯ÛŒÚº Ø§ÙˆØ± Ú†Ù„Ø§Ø¦ÛŒÚº Û” | G2010: Imported | H2010: Automatic | I2010: Used
A2011: 1079560608 | B2011: Petrol | C2011: Lahore | D2011: Original | E2011: Shadman 2, Karachi | F2011: Suzuki bolan petrosal cng suspension perfect brand new tyre with alarm install sound system ok interior neat and clean location nagan choring contact number zero Three dubal One two zero six Three dubal two nine | G2011: Local | H2011: Manual | I2011: Used
A2012: 1079561776 | B2012: Petrol | C2012: Lahore | D2012: Original | E2012: Scheme 33 - Sector 18-A, Karachi | F2012: A. Salam I am selling my Honda city 2017/18 in mint condition. Car ma 1 minor sa touch up hai scratches hai thora bohat. Everything is excellent just buy and drive urgent sell karni hai I am not a broker so broker wala rate nahi lagana 33 lakh sa kaam wala call nahi kara serious buyer contact kara Thank you | G2012: Local | H2012: Automatic | I2012: Used
A2013: 1079562921 | B2013: Petrol | C2013: Multan | D2013: Original | E2013: Chungi No. 5, Kabirwala | F2013: new condition dual ac fog lights (no work required) new tires no teaching please serious people contact me | G2013: Imported | H2013: Manual | I2013: Used
A2014: 1079563213 | B2014: Petrol | C2014: Sindh | D2014: Original | E2014: Sardargarhi, Peshawar | F2014: Kia sportage 2002 madal karchi nambar 2000cc petrol engine and double cylinder cng One my name Smart card available file and hand Spray on outside, genuine on inside New tire and new rim Alarm W N (O321)9O\6O\634\ | G2014: Imported | H2014: Manual | I2014: Used
...

Sheet Tasks
A1: Ad ID | B1: Car_Name | C1: Make | D1: Make Model | E1: Year | F1: KM_driven | G1: Price | H1: Fuel | I1: Registration_city | J1: Assembly | K1: Transmission | L1: Condition | M1: Selection | N1: Len | O1: Model | P1: Miles_per_year
A2: 1019823763 | B2: Toyota Corolla Altis 1.6 cc | C2: Toyota | D2: Toyota Corrolla Altis | E2: 2015 | F2: 130000 | G2: 4000000 | H2: {=VLOOKUP(A2,Cars_dataset_sheet2!A:I,{2,3,7,8,9},FALSE)} -> Petrol | I2: Karachi | J2: Local | K2: Automatic | L2: Used | M2: =IF(AND(OR(H2="Petrol", H2="CNG"), I2<>"Karachi", NOT(OR(C2="Toyota", C2="Honda"))), "SELECTED", "NOT SELECTED") -> NOT SELECTED | N2: =LEN(D2) -> 21 | O2: =RIGHT(D2, LEN(D2) - FIND(" ", D2)) -> Corrolla Altis | P2: =ROUND((2025-E2),3) -> 10 | S2: , E2))_x000D_
A3: 1032353392 | B3: Mitsubishi mini cab urgent sale | C3: Mitsubishi | D3: Mitsubishi Minica | E3: 2012 | F3: 115000 | G3: 1150000 | H3: {=VLOOKUP(A3,Cars_dataset_sheet2!A:I,{2,3,7,8,9},FALSE)} -> Petrol | I3: Lahore | J3: Imported | K3: Automatic | L3: Used | M3: =IF(AND(OR(H3="Petrol", H3="CNG"), I3<>"Karachi", NOT(OR(C3="Toyota", C3="Honda"))), "SELECTED", "NOT SELECTED") -> SELECTED | N3: =LEN(D3) -> 17 | O3: =RIGHT(D3, LEN(D3) - FIND(" ", D3)) -> Minica | P3: =ROUND((2025-E3),3) -> 13
A4: 1035626806 | B4: Suzuki Every 2013 Model 2019 Registered Jet Black Single hand Use A+ C | C4: Suzuki | D4: Suzuki Every | E4: 2013 | F4: 120000 | G4: 1900000 | H4: {=VLOOKUP(A4,Cars_dataset_sheet2!A:I,{2,3,7,8,9},FALSE)} -> Petrol | I4: Lahore | J4: Imported | K4: Automatic | L4: Used | M4: =IF(AND(OR(H4="Petrol", H4="CNG"), I4<>"Karachi", NOT(OR(C4="Toyota", C4="Honda"))), "SELECTED", "NOT SELECTED") -> SELECTED | N4: =LEN(D4) -> 12 | O4: =RIGHT(D4, LEN(D4) - FIND(" ", D4)) -> Every | P4: =ROUND((2025-E4),3) -> 12
A5: 1036683049 | B5: Mehran 2016 VXR original condition | C5: Suzuki | D5: Suzuki Mehran VXR | E5: 2016 | F5: 38500 | G5: 1180000 | H5: {=VLOOKUP(A5,Cars_dataset_sheet2!A:I,{2,3,7,8,9},FALSE)} -> Petrol | I5: Hyderabad | J5: Local | K5: Manual | L5: Used | M5: =IF(AND(OR(H5="Petrol", H5="CNG"), I5<>"Karachi", NOT(OR(C5="Toyota", C5="Honda"))), "SELECTED", "NOT SELECTED") -> SELECTED | N5: =LEN(D5) -> 17 | O5: =RIGHT(D5, LEN(D5) - FIND(" ", D5)) -> Mehran VXR | P5: =ROUND((2025-E5),3) -> 9
A6: 1036970933 | B6: Daihatsu Cuore 2004 | C6: Daihatsu | D6: Daihatsu Cuore | E6: 2004 | F6: 100000 | G6: 700000 | H6: {=VLOOKUP(A6,Cars_dataset_sheet2!A:I,{2,3,7,8,9},FALSE)} -> Petrol | I6: Karachi | J6: Local | K6: Manual | L6: Used | M6: =IF(AND(OR(H6="Petrol", H6="CNG"), I6<>"Karachi", NOT(OR(C6="Toyota", C6="Honda"))), "SELECTED", "NOT SELECTED") -> NOT SELECTED | N6: =LEN(D6) -> 14 | O6: =RIGHT(D6, LEN(D6) - FIND(" ", D6)) -> Cuore | P6: =ROUND((2025-E6),3) -> 21
A7: 1038612589 | B7: Mitsubishi Minica 2 door Japanese Car for sale | C7: Mitsubishi | D7: Mitsubishi Minica | E7: 2007 | F7: 133500 | G7: 1300000 | H7: {=VLOOKUP(A7,Cars_dataset_sheet2!A:I,{2,3,7,8,9},FALSE)} -> Petrol | I7: Lahore | J7: Imported | K7: Manual | L7: Used | M7: =IF(AND(OR(H7="Petrol", H7="CNG"), I7<>"Karachi", NOT(OR(C7="Toyota", C7="Honda"))), "SELECTED", "NOT SELECTED") -> SELECTED | N7: =LEN(D7) -> 17 | O7: =RIGHT(D7, LEN(D7) - FIND(" ", D7)) -> Minica | P7: =ROUND((2025-E7),3) -> 18
A8: 1043285959 | B8: toyota corolla 2005 | C8: Toyota | D8: Toyota Corolla XLI | E8: 2005 | F8: 195000 | G8: 1750000 | H8: {=VLOOKUP(A8,Cars_dataset_sheet2!A:I,{2,3,7,8,9},FALSE)} -> Petrol | I8: Islamabad | J8: Local | K8: Manual | L8: Used | M8: =IF(AND(OR(H8="Petrol", H8="CNG"), I8<>"Karachi", NOT(OR(C8="Toyota", C8="Honda"))), "SELECTED", "NOT SELECTED") -> NOT SELECTED | N8: =LEN(D8) -> 18 | O8: =RIGHT(D8, LEN(D8) - FIND(" ", D8)) -> Corolla XLI | P8: =ROUND((2025-E8),3) -> 20
A9: 1043893641 | B9: chska party call na kra | C9: KIA | D9: KIA Classic | E9: 2005 | F9: 129049 | G9: 550000 | H9: {=VLOOKUP(A9,Cars_dataset_sheet2!A:I,{2,3,7,8,9},FALSE)} -> Petrol | I9: Islamabad | J9: Local | K9: Manual | L9: Used | M9: =IF(AND(OR(H9="Petrol", H9="CNG"), I9<>"Karachi", NOT(OR(C9="Toyota", C9="Honda"))), "SELECTED", "NOT SELECTED") -> SELECTED | N9: =LEN(D9) -> 11 | O9: =RIGHT(D9, LEN(D9) - FIND(" ", D9)) -> Classic | P9: =ROUND((2025-E9),3) -> 20
A10: 1045295959 | B10: Suzuki Wagon R FA Package 2019 Model 2022 Fresh Import 17360 Km driven | C10: Suzuki | D10: Suzuki Wagon R | E10: 2019 | F10: 18360 | G10: 3500000 | H10: {=VLOOKUP(A10,Cars_dataset_sheet2!A:I,{2,3,7,8,9},FALSE)} -> Petrol | I10: Unregistered | J10: Imported | K10: Automatic | L10: Used | M10: =IF(AND(OR(H10="Petrol", H10="CNG"), I10<>"Karachi", NOT(OR(C10="Toyota", C10="Honda"))), "SELECTED", "NOT SELECTED") -> SELECTED | N10: =LEN(D10) -> 14 | O10: =RIGHT(D10, LEN(D10) - FIND(" ", D10)) -> Wagon R | P10: =ROUND((2025-E10),3) -> 6
A11: 1045445134 | B11: Carry Daaba Minicap Mitsubishi | C11: Mitsubishi | D11: Mitsubishi Minica | E11: 2017 | F11: 170000 | G11: 1500000 | H11: {=VLOOKUP(A11,Cars_dataset_sheet2!A:I,{2,3,7,8,9},FALSE)} -> Petrol | I11: Lahore | J11: Imported | K11: Automatic | L11: Used | M11: =IF(AND(OR(H11="Petrol", H11="CNG"), I11<>"Karachi", NOT(OR(C11="Toyota", C11="Honda"))), "SELECTED", "NOT SELECTED") -> SELECTED | N11: =LEN(D11) -> 17 | O11: =RIGHT(D11, LEN(D11) - FIND(" ", D11)) -> Minica | P11: =ROUND((2025-E11),3) -> 8
A12: 1046475308 | B12: Kia Spectra 2001 1.5 Automatic. Customised price negotiable hai jaldi | C12: KIA | D12: KIA Spectra | E12: 2001 | F12: 50000 | G12: 1200000 | H12: {=VLOOKUP(A12,Cars_dataset_sheet2!A:I,{2,3,7,8,9},FALSE)} -> Petrol | I12: Lahore | J12: Imported | K12: Automatic | L12: Used | M12: =IF(AND(OR(H12="Petrol", H12="CNG"), I12<>"Karachi", NOT(OR(C12="Toyota", C12="Honda"))), "SELECTED", "NOT SELECTED") -> SELECTED | N12: =LEN(D12) -> 11 | O12: =RIGHT(D12, LEN(D12) - FIND(" ", D12)) -> Spectra | P12: =ROUND((2025-E12),3) -> 24
A13: 1046608801 | B13: suzuki every turbo 5gair Exchange posibl with Honda&corola 03195517118 | C13: Suzuki | D13: Suzuki Every | E13: 2016 | F13: 123456 | G13: 1750000 | H13: {=VLOOKUP(A13,Cars_dataset_sheet2!A:I,{2,3,7,8,9},FALSE)} -> Petrol | I13: Lahore | J13: Imported | K13: Automatic | L13: Used | M13: =IF(AND(OR(H13="Petrol", H13="CNG"), I13<>"Karachi", NOT(OR(C13="Toyota", C13="Honda"))), "SELECTED", "NOT SELECTED") -> SELECTED | N13: =LEN(D13) -> 12 | O13: =RIGHT(D13, LEN(D13) - FIND(" ", D13)) -> Every | P13: =ROUND((2025-E13),3) -> 9
A14: 1046845167 | B14: Suzuki Bolan | C14: Suzuki | D14: Suzuki Bolan | E14: 2017 | F14: 38000 | G14: 1300000 | H14: {=VLOOKUP(A14,Cars_dataset_sheet2!A:I,{2,3,7,8,9},FALSE)} -> Petrol | I14: Karachi | J14: Local | K14: Manual | L14: Used | M14: =IF(AND(OR(H14="Petrol", H14="CNG"), I14<>"Karachi", NOT(OR(C14="Toyota", C14="Honda"))), "SELECTED", "NOT SELECTED") -> NOT SELECTED | N14: =LEN(D14) -> 12 | O14: =RIGHT(D14, LEN(D14) - FIND(" ", D14)) -> Bolan | P14: =ROUND((2025-E14),3) -> 8
... A498: 1076289664 | B498: Carry Bolin | C498: Suzuki | D498: Suzuki Bolan | E498: 2019 | F498: 12345 | G498: 1350000 | H498: {=VLOOKUP(A498,Cars_dataset_sheet2!A:I,{2,3,7,8,9},FALSE)} -> CNG | I498: Karachi | J498: Local | K498: Manual | L498: Used | M498: =IF(AND(OR(H498="Petrol", H498="CNG"), I498<>"Karachi", NOT(OR(C498="Toyota", C498="Honda"))), "SELECTED", "NOT SELECTED") -> NOT SELECTED | N498: =LEN(D498) -> 12 | O498: =RIGHT(D498, LEN(D498) - FIND(" ", D498)) -> Bolan | P498: =ROUND((2025-E498),3) -> 6
A499: 1076304786 | B499: 3119111071 | C499: Suzuki | D499: Suzuki Bolan | E499: 2010 | F499: 70000 | G499: 850000 | H499: {=VLOOKUP(A499,Cars_dataset_sheet2!A:I,{2,3,7,8,9},FALSE)} -> CNG | I499: Lahore | J499: Imported | K499: Manual | L499: Used | M499: =IF(AND(OR(H499="Petrol", H499="CNG"), I499<>"Karachi", NOT(OR(C499="Toyota", C499="Honda"))), "SELECTED", "NOT SELECTED") -> SELECTED | N499: =LEN(D499) -> 12 | O499: =RIGHT(D499, LEN(D499) - FIND(" ", D499)) -> Bolan | P499: =ROUND((2025-E499),3) -> 15
A500: 1076307705 | B500: Dihatshu Mira 2012/15 New Condition Exchange with Alto Vxr | C500: Daihatsu | D500: Daihatsu Mira | E500: 2015 | F500: 99000 | G500: 2300000 | H500: {=VLOOKUP(A500,Cars_dataset_sheet2!A:I,{2,3,7,8,9},FALSE)} -> Petrol | I500: Lahore | J500: Imported | K500: Automatic | L500: Used | M500: =IF(AND(OR(H500="Petrol", H500="CNG"), I500<>"Karachi", NOT(OR(C500="Toyota", C500="Honda"))), "SELECTED", "NOT SELECTED") -> SELECTED | N500: =LEN(D500) -> 13 | O500: =RIGHT(D500, LEN(D500) - FIND(" ", D500)) -> Mira | P500: =ROUND((2025-E500),3) -> 10
A501: 1076311882 | B501: Mehran VXR 2008 | C501: Suzuki | D501: Suzuki Mehran VXR | E501: 2008 | F501: 50000 | G501: 750000 | H501: {=VLOOKUP(A501,Cars_dataset_sheet2!A:I,{2,3,7,8,9},FALSE)} -> Petrol | I501: Multan | J501: Local | K501: Manual | L501: Used | M501: =IF(AND(OR(H501="Petrol", H501="CNG"), I501<>"Karachi", NOT(OR(C501="Toyota", C501="Honda"))), "SELECTED", "NOT SELECTED") -> SELECTED | N501: =LEN(D501) -> 17 | O501: =RIGHT(D501, LEN(D501) - FIND(" ", D501)) -> Mehran VXR | P501: =ROUND((2025-E501),3) -> 17
A502: 1076312655 | B502: KIA PICANTO 1.0 AT | C502: KIA | D502: KIA Picanto | E502: 2021 | F502: 18500 | G502: 3150000 | H502: {=VLOOKUP(A502,Cars_dataset_sheet2!A:I,{2,3,7,8,9},FALSE)} -> Petrol | I502: Karachi | J502: Local | K502: Automatic | L502: Used | M502: =IF(AND(OR(H502="Petrol", H502="CNG"), I502<>"Karachi", NOT(OR(C502="Toyota", C502="Honda"))), "SELECTED", "NOT SELECTED") -> NOT SELECTED | N502: =LEN(D502) -> 11 | O502: =RIGHT(D502, LEN(D502) - FIND(" ", D502)) -> Picanto | P502: =ROUND((2025-E502),3) -> 4
A503: 1076320957 | B503: City 2009 -Prosmatic | C503: Honda | D503: Honda City IVTEC | E503: 2009 | F503: 146000 | G503: 2200000 | H503: {=VLOOKUP(A503,Cars_dataset_sheet2!A:I,{2,3,7,8,9},FALSE)} -> Petrol | I503: Sialkot | J503: Local | K503: Automatic | L503: Used | M503: =IF(AND(OR(H503="Petrol", H503="CNG"), I503<>"Karachi", NOT(OR(C503="Toyota", C503="Honda"))), "SELECTED", "NOT SELECTED") -> NOT SELECTED | N503: =LEN(D503) -> 16 | O503: =RIGHT(D503, LEN(D503) - FIND(" ", D503)) -> City IVTEC | P503: =ROUND((2025-E503),3) -> 16
A504: 1076322359 | B504: Santro Club 2004 Urgent Sale | C504: Hyundai | D504: Hyundai Santro | E504: 2004 | F504: 99000 | G504: 650000 | H504: {=VLOOKUP(A504,Cars_dataset_sheet2!A:I,{2,3,7,8,9},FALSE)} -> Petrol | I504: Karachi | J504: Imported | K504: Manual | L504: Used | M504: =IF(AND(OR(H504="Petrol", H504="CNG"), I504<>"Karachi", NOT(OR(C504="Toyota", C504="Honda"))), "SELECTED", "NOT SELECTED") -> NOT SELECTED | N504: =LEN(D504) -> 14 | O504: =RIGHT(D504, LEN(D504) - FIND(" ", D504)) -> Santro | P504: =ROUND((2025-E504),3) -> 21
A505: 1076323992 | B505: Mira Package XSA3 Like a Brand New Car | C505: Daihatsu | D505: Daihatsu Mira | E505: 2019 | F505: 115000 | G505: 3550000 | H505: {=VLOOKUP(A505,Cars_dataset_sheet2!A:I,{2,3,7,8,9},FALSE)} -> Petrol | I505: Karachi | J505: Imported | K505: Automatic | L505: Used | M505: =IF(AND(OR(H505="Petrol", H505="CNG"), I505<>"Karachi", NOT(OR(C505="Toyota", C505="Honda"))), "SELECTED", "NOT SELECTED") -> NOT SELECTED | N505: =LEN(D505) -> 13 | O505: =RIGHT(D505, LEN(D505) - FIND(" ", D505)) -> Mira | P505: =ROUND((2025-E505),3) -> 6
A506: 1076340262 | B506: Carolla Altis 1.6 | C506: Toyota | D506: Toyota Corrolla Altis | E506: 2017 | F506: 90000 | G506: 3900000 | H506: {=VLOOKUP(A506,Cars_dataset_sheet2!A:I,{2,3,7,8,9},FALSE)} -> Petrol | I506: Karachi | J506: Local | K506: Automatic | L506: Used | M506: =IF(AND(OR(H506="Petrol", H506="CNG"), I506<>"Karachi", NOT(OR(C506="Toyota", C506="Honda"))), "SELECTED", "NOT SELECTED") -> NOT SELECTED | N506: =LEN(D506) -> 21 | O506: =RIGHT(D506, LEN(D506) - FIND(" ", D506)) -> Corrolla Altis | P506: =ROUND((2025-E506),3) -> 8
A507: 1076347671 | B507: KIA SPECTRA IN V GOOD CONDITION. (O3OO55O6699) | C507: KIA | D507: KIA Spectra | E507: 2002 | F507: 1234 | G507: 520000 | H507: {=VLOOKUP(A507,Cars_dataset_sheet2!A:I,{2,3,7,8,9},FALSE)} -> Petrol | I507: Sindh | J507: Imported | K507: Manual | L507: Used | M507: =IF(AND(OR(H507="Petrol", H507="CNG"), I507<>"Karachi", NOT(OR(C507="Toyota", C507="Honda"))), "SELECTED", "NOT SELECTED") -> SELECTED | N507: =LEN(D507) -> 11 | O507: =RIGHT(D507, LEN(D507) - FIND(" ", D507)) -> Spectra | P507: =ROUND((2025-E507),3) -> 23
A508: 1076356020 | B508: every 07/12 for sale or Xchang Toyota car | C508: Suzuki | D508: Suzuki Every | E508: 2012 | F508: 200000 | G508: 1260000 | H508: {=VLOOKUP(A508,Cars_dataset_sheet2!A:I,{2,3,7,8,9},FALSE)} -> Petrol | I508: Lahore | J508: Imported | K508: Automatic | L508: Used | M508: =IF(AND(OR(H508="Petrol", H508="CNG"), I508<>"Karachi", NOT(OR(C508="Toyota", C508="Honda"))), "SELECTED", "NOT SELECTED") -> SELECTED | N508: =LEN(D508) -> 12 | O508: =RIGHT(D508, LEN(D508) - FIND(" ", D508)) -> Every | P508: =ROUND((2025-E508),3) -> 13
A509: 1076380433 | B509: suzuki Alto vxr | C509: Suzuki | D509: Suzuki Alto | E509: 2012 | F509: 143000 | G509: 1020000 | H509: {=VLOOKUP(A509,Cars_dataset_sheet2!A:I,{2,3,7,8,9},FALSE)} -> Petrol | I509: Karachi | J509: Local | K509: Manual | L509: Used | M509: =IF(AND(OR(H509="Petrol", H509="CNG"), I509<>"Karachi", NOT(OR(C509="Toyota", C509="Honda"))), "SELECTED", "NOT SELECTED") -> NOT SELECTED | N509: =LEN(D509) -> 11 | O509: =RIGHT(D509, LEN(D509) - FIND(" ", D509)) -> Alto | P509: =ROUND((2025-E509),3) -> 13
A510: 1076380992 | B510: Altis 1.6 automatic 2020/2021 for sale | C510: Toyota | D510: Toyota Corrolla Altis | E510: 2020 | F510: 58000 | G510: 4400000 | H510: {=VLOOKUP(A510,Cars_dataset_sheet2!A:I,{2,3,7,8,9},FALSE)} -> Petrol | I510: Karachi | J510: Local | K510: Automatic | L510: Used | M510: =IF(AND(OR(H510="Petrol", H510="CNG"), I510<>"Karachi", NOT(OR(C510="Toyota", C510="Honda"))), "SELECTED", "NOT SELECTED") -> NOT SELECTED | N510: =LEN(D510) -> 21 | O510: =RIGHT(D510, LEN(D510) - FIND(" ", D510)) -> Corrolla Altis | P510: =ROUND((2025-E510),3) -> 5
A511: 1076385717 | B511: Hyndai santro club 2003 | C511: Hyundai | D511: Hyundai Santro | E511: 2003 | F511: 5555 | G511: 780000 | H511: {=VLOOKUP(A511,Cars_dataset_sheet2!A:I,{2,3,7,8,9},FALSE)} -> Petrol | I511: Lahore | J511: Imported | K511: Manual | L511: Used | M511: =IF(AND(OR(H511="Petrol", H511="CNG"), I511<>"Karachi", NOT(OR(C511="Toyota", C511="Honda"))), "SELECTED", "NOT SELECTED") -> SELECTED | N511: =LEN(D511) -> 14 | O511: =RIGHT(D511, LEN(D511) - FIND(" ", D511)) -> Santro | P511: =ROUND((2025-E511),3) -> 22
... A730: 1077566598 | B730: 1.5 Honda City Aspire in Brand New Condition | C730: Honda | D730: Honda City Aspire | E730: 2017 | F730: 51000 | G730: 3250000 | H730: {=VLOOKUP(A730,Cars_dataset_sheet2!A:I,{2,3,7,8,9},FALSE)} -> Petrol | I730: Karachi | J730: Local | K730: Manual | L730: Used | M730: =IF(AND(OR(H730="Petrol", H730="CNG"), I730<>"Karachi", NOT(OR(C730="Toyota", C730="Honda"))), "SELECTED", "NOT SELECTED") -> NOT SELECTED | N730: =LEN(D730) -> 17 | O730: =RIGHT(D730, LEN(D730) - FIND(" ", D730)) -> City Aspire | P730: =ROUND((2025-E730),3) -> 8
A731: 1077567793 | B731: 3002195137 | C731: Suzuki | D731: Suzuki Bolan | E731: 2017 | F731: 62000 | G731: 1150000 | H731: {=VLOOKUP(A731,Cars_dataset_sheet2!A:I,{2,3,7,8,9},FALSE)} -> Petrol | I731: Karachi | J731: Imported | K731: Manual | L731: Used | M731: =IF(AND(OR(H731="Petrol", H731="CNG"), I731<>"Karachi", NOT(OR(C731="Toyota", C731="Honda"))), "SELECTED", "NOT SELECTED") -> NOT SELECTED | N731: =LEN(D731) -> 12 | O731: =RIGHT(D731, LEN(D731) - FIND(" ", D731)) -> Bolan | P731: =ROUND((2025-E731),3) -> 8
A732: 1077572197 | B732: Mitsubishi Lancer 2005 model in good condition | C732: Mitsubishi | D732: Mitsubishi Lancer | E732: 2005 | F732: 70000 | G732: 1370000 | H732: {=VLOOKUP(A732,Cars_dataset_sheet2!A:I,{2,3,7,8,9},FALSE)} -> Petrol | I732: Lahore | J732: Imported | K732: Manual | L732: Used | M732: =IF(AND(OR(H732="Petrol", H732="CNG"), I732<>"Karachi", NOT(OR(C732="Toyota", C732="Honda"))), "SELECTED", "NOT SELECTED") -> SELECTED | N732: =LEN(D732) -> 17 | O732: =RIGHT(D732, LEN(D732) - FIND(" ", D732)) -> Lancer | P732: =ROUND((2025-E732),3) -> 20
A733: 1077576628 | B733: dihatsu move urgent sale | C733: Daihatsu | D733: Daihatsu Move | E733: 2021 | F733: 100000 | G733: 2900000 | H733: {=VLOOKUP(A733,Cars_dataset_sheet2!A:I,{2,3,7,8,9},FALSE)} -> Petrol | I733: Punjab | J733: Imported | K733: Automatic | L733: Used | M733: =IF(AND(OR(H733="Petrol", H733="CNG"), I733<>"Karachi", NOT(OR(C733="Toyota", C733="Honda"))), "SELECTED", "NOT SELECTED") -> SELECTED | N733: =LEN(D733) -> 13 | O733: =RIGHT(D733, LEN(D733) - FIND(" ", D733)) -> Move | P733: =ROUND((2025-E733),3) -> 4
A734: 1077577910 | B734: honda city 2010 | C734: Honda | D734: Honda City IVTEC | E734: 2010 | F734: 145000 | G734: 2500000 | H734: {=VLOOKUP(A734,Cars_dataset_sheet2!A:I,{2,3,7,8,9},FALSE)} -> Petrol | I734: Lahore | J734: Local | K734: Manual | L734: Used | M734: =IF(AND(OR(H734="Petrol", H734="CNG"), I734<>"Karachi", NOT(OR(C734="Toyota", C734="Honda"))), "SELECTED", "NOT SELECTED") -> NOT SELECTED | N734: =LEN(D734) -> 16 | O734: =RIGHT(D734, LEN(D734) - FIND(" ", D734)) -> City IVTEC | P734: =ROUND((2025-E734),3) -> 15
A735: 1077578497 | B735: Honda civic reborn | C735: Honda | D735: Honda Civic Prosmetic | E735: 2009 | F735: 97000 | G735: 1800000 | H735: {=VLOOKUP(A735,Cars_dataset_sheet2!A:I,{2,3,7,8,9},FALSE)} -> Petrol | I735: Sindh | J735: Local | K735: Automatic | L735: Used | M735: =IF(AND(OR(H735="Petrol", H735="CNG"), I735<>"Karachi", NOT(OR(C735="Toyota", C735="Honda"))), "SELECTED", "NOT SELECTED") -> NOT SELECTED | N735: =LEN(D735) -> 21 | O735: =RIGHT(D735, LEN(D735) - FIND(" ", D735)) -> Civic Prosmetic | P735: =ROUND((2025-E735),3) -> 16
A736: 1077580298 | B736: Cuore 2012 | C736: Daihatsu | D736: Daihatsu Cuore | E736: 2012 | F736: 120000 | G736: 865000 | H736: {=VLOOKUP(A736,Cars_dataset_sheet2!A:I,{2,3,7,8,9},FALSE)} -> Petrol | I736: Sindh | J736: Imported | K736: Manual | L736: Used | M736: =IF(AND(OR(H736="Petrol", H736="CNG"), I736<>"Karachi", NOT(OR(C736="Toyota", C736="Honda"))), "SELECTED", "NOT SELECTED") -> SELECTED | N736: =LEN(D736) -> 14 | O736: =RIGHT(D736, LEN(D736) - FIND(" ", D736)) -> Cuore | P736: =ROUND((2025-E736),3) -> 13
A737: 1077583006 | B737: honda city 1.3 Mt | C737: Honda | D737: Honda City IVTEC | E737: 2019 | F737: 58000 | G737: 3500000 | H737: {=VLOOKUP(A737,Cars_dataset_sheet2!A:I,{2,3,7,8,9},FALSE)} -> Petrol | I737: Lahore | J737: Local | K737: Manual | L737: Used | M737: =IF(AND(OR(H737="Petrol", H737="CNG"), I737<>"Karachi", NOT(OR(C737="Toyota", C737="Honda"))), "SELECTED", "NOT SELECTED") -> NOT SELECTED | N737: =LEN(D737) -> 16 | O737: =RIGHT(D737, LEN(D737) - FIND(" ", D737)) -> City IVTEC | P737: =ROUND((2025-E737),3) -> 6
A738: 1077583460 | B738: Ek Wagon 2008/2013 [660cc] | C738: Mitsubishi | D738: Mitsubishi Ek Wagon | E738: 2008 | F738: 140000 | G738: 1700000 | H738: {=VLOOKUP(A738,Cars_dataset_sheet2!A:I,{2,3,7,8,9},FALSE)} -> Petrol | I738: Punjab | J738: Imported | K738: Manual | L738: Used | M738: =IF(AND(OR(H738="Petrol", H738="CNG"), I738<>"Karachi", NOT(OR(C738="Toyota", C738="Honda"))), "SELECTED", "NOT SELECTED") -> SELECTED | N738: =LEN(D738) -> 19 | O738: =RIGHT(D738, LEN(D738) - FIND(" ", D738)) -> Ek Wagon | P738: =ROUND((2025-E738),3) -> 17
A739: 1077592008 | B739: Mercedes C 200 Kompressor | C739: Mercedes | D739: Mercedes C Class | E739: 2003 | F739: 200000 | G739: 2300000 | H739: {=VLOOKUP(A739,Cars_dataset_sheet2!A:I,{2,3,7,8,9},FALSE)} -> Petrol | I739: Sindh | J739: Imported | K739: Automatic | L739: Used | M739: =IF(AND(OR(H739="Petrol", H739="CNG"), I739<>"Karachi", NOT(OR(C739="Toyota", C739="Honda"))), "SELECTED", "NOT SELECTED") -> SELECTED | N739: =LEN(D739) -> 16 | O739: =RIGHT(D739, LEN(D739) - FIND(" ", D739)) -> C Class | P739: =ROUND((2025-E739),3) -> 22
A740: 1077609801 | B740: i am selling my lancer glx 1.5 automatic | C740: Mitsubishi | D740: Mitsubishi Lancer | E740: 2006 | F740: 65000 | G740: 1550000 | H740: {=VLOOKUP(A740,Cars_dataset_sheet2!A:I,{2,3,7,8,9},FALSE)} -> Petrol | I740: Karachi | J740: Imported | K740: Automatic | L740: Used | M740: =IF(AND(OR(H740="Petrol", H740="CNG"), I740<>"Karachi", NOT(OR(C740="Toyota", C740="Honda"))), "SELECTED", "NOT SELECTED") -> NOT SELECTED | N740: =LEN(D740) -> 17 | O740: =RIGHT(D740, LEN(D740) - FIND(" ", D740)) -> Lancer | P740: =ROUND((2025-E740),3) -> 19
A741: 1077612923 | B741: Mira model 2014 registration 2017 | C741: Daihatsu | D741: Daihatsu Mira | E741: 2014 | F741: 119000 | G741: 2460000 | H741: {=VLOOKUP(A741,Cars_dataset_sheet2!A:I,{2,3,7,8,9},FALSE)} -> Petrol | I741: Karachi | J741: Imported | K741: Automatic | L741: Used | M741: =IF(AND(OR(H741="Petrol", H741="CNG"), I741<>"Karachi", NOT(OR(C741="Toyota", C741="Honda"))), "SELECTED", "NOT SELECTED") -> NOT SELECTED | N741: =LEN(D741) -> 13 | O741: =RIGHT(D741, LEN(D741) - FIND(" ", D741)) -> Mira | P741: =ROUND((2025-E741),3) -> 11
...

Sheet Question Answers
A2: Answer no 1 | E2: Answer no 2 | I2: Answer no 3 | M2: Answer no 4 | S2: Answer no 5
A4: Make | B4: Suzuki | E4: Make | F4: Honda | I4: Registration_city | J4: Karachi | M4: Count of Ad ID | N4: Column Labels | S4: Count of Ad ID | T4: Column Labels
E5: Transmission | F5: Automatic | I5: Assembly | J5: Imported | M5: Row Labels | N5: Automatic | O5: Manual | P5: Grand Total | S5: Row Labels | T5: Imported | U5: Local | V5: Grand Total
A6: Row Labels | B6: Average of Price | E6: Assembly | F6: Local | M6: Abbottabad | N6: 0 | O6: 1 | P6: 1 | S6: Abbottabad | T6: 0 | U6: 0.0004456328 | V6: 0.0004456328
A7: Alto | B7: 1565165.5 | I7: Row Labels | J7: Max of Price | M7: Arifwala | N7: 0 | O7: 1 | P7: 1 | S7: Arifwala | T7: 0.0001114082 | U7: 0 | V7: 0.0001114082
A8: Baleno | B8: 909113.62 | E8: Row Labels | F8: Count of Ad ID | I8: Changan | J8: 3900000 | M8: Attock | N8: 0 | O8: 1 | P8: 1 | S8: Attock | T8: 0.0002228164 | U8: 0.0001114082 | V8: 0.0003342246
A9: Bolan | B9: 1021034.8 | E9: Bahawalpur | F9: 1 | I9: Chevrolet | J9: 1050000 | M9: Badin | N9: 1 | O9: 0 | P9: 1 | S9: Badin | T9: 0.0001114082 | U9: 0 | V9: 0.0001114082
A10: Cervo | B10: 1345000 | E10: Bannu | F10: 1 | I10: Daihatsu | J10: 4080000 | M10: Bahawalnagar | N10: 0 | O10: 1 | P10: 1 | S10: Bahawalnagar | T10: 0 | U10: 0.0001114082 | V10: 0.0001114082
A11: Cultus VXL | B11: 650000 | E11: Faisalabad | F11: 7 | I11: FAW | J11: 1500000 | M11: Bahawalpur | N11: 0.22222222 | O11: 0.77777778 | P11: 1 | S11: Bahawalpur | T11: 0.0002228164 | U11: 0.0017825312 | V11: 0.0020053476
A12: Cultus VXR | B12: 1198606.7 | E12: Gujranwala | F12: 1 | I12: Honda | J12: 4600000 | M12: Bannu | N12: 1 | O12: 0 | P12: 1 | S12: Bannu | T12: 0 | U12: 0.0002228164 | V12: 0.0002228164
A13: Every | B13: 1767351.2 | E13: Gujrat | F13: 1 | I13: Hyundai | J13: 1000000 | M13: Bhakkar | N13: 0 | O13: 1 | P13: 1 | S13: Bhakkar | T13: 0 | U13: 0.0001114082 | V13: 0.0001114082
A14: Every Wagon | B14: 2275000 | E14: Islamabad | F14: 100 | I14: KIA | J14: 3350000 | M14: Bhimber | N14: 0 | O14: 1 | P14: 1 | S14: Bhimber | T14: 0 | U14: 0.0001114082 | V14: 0.0001114082
A15: Khyber | B15: 185000 | E15: Karachi | F15: 227 | I15: Mercedes | J15: 4600000 | M15: Charsadda | N15: 0 | O15: 1 | P15: 1 | S15: Charsadda | T15: 0 | U15: 0.0001114082 | V15: 0.0001114082
A16: Liana | B16: 1250000 | E16: Lahore | F16: 304 | I16: Mitsubishi | J16: 3200000 | M16: Chiniot | N16: 0 | O16: 1 | P16: 1 | S16: Chiniot | T16: 0.0001114082 | U16: 0.0001114082 | V16: 0.0002228164
A17: Mehran VX | B17: 842500 | E17: Multan | F17: 4 | I17: Suzuki | J17: 2800000 | M17: Chishtian Mandi | N17: 0 | O17: 1 | P17: 1 | S17: Chishtian Mandi | T17: 0 | U17: 0.0001114082 | V17: 0.0001114082
A18: Mehran VXR | B18: 902563.22 | E18: Peshawar | F18: 3 | I18: Toyota | J18: 4990000 | M18: Dadu | N18: 0 | O18: 1 | P18: 1 | S18: Dadu | T18: 0 | U18: 0.0001114082 | V18: 0.0001114082
A19: Ravi | B19: 984296.3 | E19: Punjab | F19: 28 | I19: Grand Total | J19: 4990000 | M19: Dera Ghazi Khan | N19: 0.25 | O19: 0.75 | P19: 1 | S19: Dera Ghazi Khan | T19: 0.0002228164 | U19: 0.0002228164 | V19: 0.0004456328
A20: Swift | B20: 2427501.7 | E20: Rawalpindi | F20: 2 | M20: Dera Ismail Khan | N20: 0 | O20: 1 | P20: 1 | S20: Dera Ismail Khan | T20: 0.0001114082 | U20: 0 | V20: 0.0001114082
A21: Wagon R | B21: 2290678.5 | E21: Sahiwal | F21: 1 | M21: Faisalabad | N21: 0.14814815 | O21: 0.85185185 | P21: 1 | S21: Faisalabad | T21: 0.006684492 | U21: 0.014371658 | V21: 0.02105615
A22: Grand Total | B22: 1482622.5 | E22: Sialkot | F22: 5 | M22: Gujranwala | N22: 0.16129032 | O22: 0.83870968 | P22: 1 | S22: Gujranwala | T22: 0.001114082 | U22: 0.0023395722 | V22: 0.0034536542
E23: Sindh | F23: 45 | M23: Gujrat | N23: 0.25 | O23: 0.75 | P23: 1 | S23: Gujrat | T23: 0.0002228164 | U23: 0.0006684492 | V23: 0.0008912656
E24: Unregistered | F24: 1 | M24: Hafizabad | N24: 0 | O24: 1 | P24: 1 | S24: Hafizabad | T24: 0.0001114082 | U24: 0 | V24: 0.0001114082
E25: Grand Total | F25: 731 | M25: Haripur | N25: 0 | O25: 1 | P25: 1 | S25: Haripur | T25: 0.0001114082 | U25: 0 | V25: 0.0001114082
M26: Hyderabad | N26: 0.30769231 | O26: 0.69230769 | P26: 1 | S26: Hyderabad | T26: 0.001114082 | U26: 0.0017825312 | V26: 0.0028966132
M27: Islamabad | N27: 0.44226044 | O27: 0.55773956 | P27: 1 | S27: Islamabad | T27: 0.045231729 | U27: 0.090797683 | V27: 0.13602941
M28: Jaranwala | N28: 0 | O28: 1 | P28: 1 | S28: Jaranwala | T28: 0.0001114082 | U28: 0 | V28: 0.0001114082
M29: Jhang Sadar | N29: 0.25 | O29: 0.75 | P29: 1 | S29: Jhang Sadar | T29: 0.0001114082 | U29: 0.0003342246 | V29: 0.0004456328
M30: Jhelum | N30: 0 | O30: 1 | P30: 1 | S30: Jhelum | T30: 0.0003342246 | U30: 0.0007798574 | V30: 0.001114082
M31: Karachi | N31: 0.47801578 | O31: 0.52198422 | P31: 1 | S31: Karachi | T31: 0.11096257 | U31: 0.18549465 | V31: 0.29645722
M32: Kasur | N32: 0 | O32: 1 | P32: 1 | S32: Kasur | T32: 0.0001114082 | U32: 0.0002228164 | V32: 0.0003342246
M33: Khanewal | N33: 0.25 | O33: 0.75 | P33: 1 | S33: Khanewal | T33: 0.0001114082 | U33: 0.0003342246 | V33: 0.0004456328
M34: Khanpur | N34: 0 | O34: 1 | P34: 1 | S34: Khanpur | T34: 0.0001114082 | U34: 0 | V34: 0.0001114082
M35: Khushab | N35: 0 | O35: 1 | P35: 1 | S35: Khushab | T35: 0.0001114082 | U35: 0 | V35: 0.0001114082
M36: Lahore | N36: 0.32374741 | O36: 0.67625259 | P36: 1 | S36: Lahore | T36: 0.1208779 | U36: 0.25490196 | V36: 0.37577986
M37: Larkana | N37: 0.33333333 | O37: 0.66666667 | P37: 1 | S37: Larkana | T37: 0.0001114082 | U37: 0.0002228164 | V37: 0.0003342246
... M67: Grand Total | N67: 0.38836898 | O67: 0.61163102 | P67: 1 | S67: Grand Total | T67: 0.34803922 | U67: 0.65196078 | V67: 1
